/var/spool/torque/mom_priv/jobs/5127342.mesabim3.msi.umn.edu.SC: line 26: 24925 Bus error               python /home/goodpast/graha682/code/python/freeze_and_thaw/cython/cmain.py /panfs/roc/groups/13/goodpast/graha682/201711_twistCAS/201712_midTwist/201712_FT/D0/2018_dftCAS/201712_ccpVTZ_NEVPT2_m06_0_2c12h24.inp > /panfs/roc/groups/13/goodpast/graha682/201711_twistCAS/201712_midTwist/201712_FT/D0/2018_dftCAS/201712_ccpVTZ_NEVPT2_m06_0_2c12h24.out
Traceback (most recent call last):
  File "/panfs/roc/msisoft/anaconda/anaconda3-5.0.1/lib/python3.6/site-packages/h5py/_hl/files.py", line 119, in make_fid
    fid = h5f.open(name, h5f.ACC_RDWR, fapl=fapl)
  File "h5py/_objects.pyx", line 54, in h5py._objects.with_phil.wrapper
  File "h5py/_objects.pyx", line 55, in h5py._objects.with_phil.wrapper
  File "h5py/h5f.pyx", line 78, in h5py.h5f.open
OSError: Unable to open file (truncated file: eof = 96, sblock->base_addr = 0, stored_eof = 2048)

During handling of the above exception, another exception occurred:

Traceback (most recent call last):
  File "/panfs/roc/msisoft/anaconda/anaconda3-5.0.1/lib/python3.6/site-packages/h5py/_hl/files.py", line 122, in make_fid
    fid = h5f.open(name, h5f.ACC_RDONLY, fapl=fapl)
  File "h5py/_objects.pyx", line 54, in h5py._objects.with_phil.wrapper
  File "h5py/_objects.pyx", line 55, in h5py._objects.with_phil.wrapper
  File "h5py/h5f.pyx", line 78, in h5py.h5f.open
OSError: Unable to open file (truncated file: eof = 96, sblock->base_addr = 0, stored_eof = 2048)

During handling of the above exception, another exception occurred:

Traceback (most recent call last):
  File "/home/goodpast/graha682/code/python/freeze_and_thaw/cython/cmain.py", line 6, in <module>
    main.main(sys.argv[1])
  File "main.pyx", line 48, in main.main
    inp = read_input(filename)
  File "read_input.pyx", line 119, in read_input.read_input
    inp.h5py = h5py.File(h5pyname)
  File "/panfs/roc/msisoft/anaconda/anaconda3-5.0.1/lib/python3.6/site-packages/h5py/_hl/files.py", line 269, in __init__
    fid = make_fid(name, mode, userblock_size, fapl, swmr=swmr)
  File "/panfs/roc/msisoft/anaconda/anaconda3-5.0.1/lib/python3.6/site-packages/h5py/_hl/files.py", line 124, in make_fid
    fid = h5f.create(name, h5f.ACC_EXCL, fapl=fapl, fcpl=fcpl)
  File "h5py/_objects.pyx", line 54, in h5py._objects.with_phil.wrapper
  File "h5py/_objects.pyx", line 55, in h5py._objects.with_phil.wrapper
  File "h5py/h5f.pyx", line 98, in h5py.h5f.create
OSError: Unable to create file (unable to open file: name = '/panfs/roc/groups/13/goodpast/graha682/201711_twistCAS/201712_midTwist/201712_FT/D0/2018_dftCAS/201712_ccpVTZ_NEVPT2_m06_0_2c12h24.hdf5', errno = 17, error message = 'File exists', flags = 15, o_flags = c2)
Overwritten attributes  get_hcore  of <class 'pyscf.dft.rks.RKS'>
Overwritten attributes  get_hcore  of <class 'pyscf.dft.rks.RKS'>
